<?xml version="1.0" encoding="UTF-8"?>
<testng-results skipped="1" failed="1" total="3" passed="1">
  <reporter-output>
  </reporter-output>
  <suite name="Default suite" duration-ms="22786" started-at="2020-11-05T11:12:07Z" finished-at="2020-11-05T11:12:29Z">
    <groups>
    </groups>
    <test name="Default test" duration-ms="22786" started-at="2020-11-05T11:12:07Z" finished-at="2020-11-05T11:12:29Z">
      <class name="com.testNG.example.testcaseDependency">
        <test-method status="PASS" signature="initializeEnvironment()[pri:0, instance:com.testNG.example.testcaseDependency@2aafb23c]" name="initializeEnvironment" duration-ms="13999" started-at="2020-11-05T16:42:07Z" finished-at="2020-11-05T16:42:21Z">
          <reporter-output>
          </reporter-output>
        </test-method> <!-- initializeEnvironment -->
        <test-method status="FAIL" signature="doLogin()[pri:0, instance:com.testNG.example.testcaseDependency@2aafb23c]" name="doLogin" duration-ms="8719" started-at="2020-11-05T16:42:21Z" depends-on-methods="com.testNG.example.testcaseDependency.initializeEnvironment" finished-at="2020-11-05T16:42:29Z">
          <exception class="java.lang.AssertionError">
            <message>
              <![CDATA[Log in successful expected [true] but found [false]]]>
            </message>
            <full-stacktrace>
              <![CDATA[java.lang.AssertionError: Log in successful expected [true] but found [false]
	at org.testng.Assert.fail(Assert.java:94)
	at org.testng.Assert.failNotEquals(Assert.java:513)
	at org.testng.Assert.assertTrue(Assert.java:42)
	at com.testNG.example.testcaseDependency.doLogin(testcaseDependency.java:48)
	at sun.reflect.NativeMethodAccessorImpl.invoke0(Native Method)
	at sun.reflect.NativeMethodAccessorImpl.invoke(NativeMethodAccessorImpl.java:62)
	at sun.reflect.DelegatingMethodAccessorImpl.invoke(DelegatingMethodAccessorImpl.java:43)
	at java.lang.reflect.Method.invoke(Method.java:497)
	at org.testng.internal.MethodInvocationHelper.invokeMethod(MethodInvocationHelper.java:86)
	at org.testng.internal.Invoker.invokeMethod(Invoker.java:643)
	at org.testng.internal.Invoker.invokeTestMethod(Invoker.java:820)
	at org.testng.internal.Invoker.invokeTestMethods(Invoker.java:1128)
	at org.testng.internal.TestMethodWorker.invokeTestMethods(TestMethodWorker.java:129)
	at org.testng.internal.TestMethodWorker.run(TestMethodWorker.java:112)
	at org.testng.TestRunner.privateRun(TestRunner.java:782)
	at org.testng.TestRunner.run(TestRunner.java:632)
	at org.testng.SuiteRunner.runTest(SuiteRunner.java:366)
	at org.testng.SuiteRunner.runSequentially(SuiteRunner.java:361)
	at org.testng.SuiteRunner.privateRun(SuiteRunner.java:319)
	at org.testng.SuiteRunner.run(SuiteRunner.java:268)
	at org.testng.SuiteRunnerWorker.runSuite(SuiteRunnerWorker.java:52)
	at org.testng.SuiteRunnerWorker.run(SuiteRunnerWorker.java:86)
	at org.testng.TestNG.runSuitesSequentially(TestNG.java:1244)
	at org.testng.TestNG.runSuitesLocally(TestNG.java:1169)
	at org.testng.TestNG.run(TestNG.java:1064)
	at org.testng.remote.RemoteTestNG.run(RemoteTestNG.java:113)
	at org.testng.remote.RemoteTestNG.initAndRun(RemoteTestNG.java:206)
	at org.testng.remote.RemoteTestNG.main(RemoteTestNG.java:177)
]]>
            </full-stacktrace>
          </exception> <!-- java.lang.AssertionError -->
          <reporter-output>
          </reporter-output>
        </test-method> <!-- doLogin -->
        <test-method status="SKIP" signature="doLogout()[pri:0, instance:com.testNG.example.testcaseDependency@2aafb23c]" name="doLogout" duration-ms="0" started-at="2020-11-05T16:42:29Z" depends-on-methods="com.testNG.example.testcaseDependency.doLogin" finished-at="2020-11-05T16:42:29Z">
          <exception class="java.lang.Throwable">
            <message>
              <![CDATA[Method testcaseDependency.doLogout()[pri:0, instance:com.testNG.example.testcaseDependency@2aafb23c] depends on not successfully finished methods]]>
            </message>
            <full-stacktrace>
              <![CDATA[java.lang.Throwable: Method testcaseDependency.doLogout()[pri:0, instance:com.testNG.example.testcaseDependency@2aafb23c] depends on not successfully finished methods
	at org.testng.internal.Invoker.invokeTestMethods(Invoker.java:1037)
	at org.testng.internal.TestMethodWorker.invokeTestMethods(TestMethodWorker.java:129)
	at org.testng.internal.TestMethodWorker.run(TestMethodWorker.java:112)
	at org.testng.TestRunner.privateRun(TestRunner.java:782)
	at org.testng.TestRunner.run(TestRunner.java:632)
	at org.testng.SuiteRunner.runTest(SuiteRunner.java:366)
	at org.testng.SuiteRunner.runSequentially(SuiteRunner.java:361)
	at org.testng.SuiteRunner.privateRun(SuiteRunner.java:319)
	at org.testng.SuiteRunner.run(SuiteRunner.java:268)
	at org.testng.SuiteRunnerWorker.runSuite(SuiteRunnerWorker.java:52)
	at org.testng.SuiteRunnerWorker.run(SuiteRunnerWorker.java:86)
	at org.testng.TestNG.runSuitesSequentially(TestNG.java:1244)
	at org.testng.TestNG.runSuitesLocally(TestNG.java:1169)
	at org.testng.TestNG.run(TestNG.java:1064)
	at org.testng.remote.RemoteTestNG.run(RemoteTestNG.java:113)
	at org.testng.remote.RemoteTestNG.initAndRun(RemoteTestNG.java:206)
	at org.testng.remote.RemoteTestNG.main(RemoteTestNG.java:177)
]]>
            </full-stacktrace>
          </exception> <!-- java.lang.Throwable -->
          <reporter-output>
          </reporter-output>
        </test-method> <!-- doLogout -->
      </class> <!-- com.testNG.example.testcaseDependency -->
    </test> <!-- Default test -->
  </suite> <!-- Default suite -->
</testng-results>
